Traceback (most recent call last):
  File "/workdir/env/lib/python3.10/site-packages/huggingface_hub/utils/_errors.py", line 261, in hf_raise_for_status
    response.raise_for_status()
  File "/workdir/env/lib/python3.10/site-packages/requests/models.py", line 1021, in raise_for_status
    raise HTTPError(http_error_msg, response=self)
requests.exceptions.HTTPError: 401 Client Error: Unauthorized for url: https://huggingface.co/meta-llama/Llama-2-7b-hf/resolve/main/config.json
The above exception was the direct cause of the following exception:
Traceback (most recent call last):
  File "/workdir/env/lib/python3.10/site-packages/transformers/utils/hub.py", line 429, in cached_file
    resolved_file = hf_hub_download(
  File "/workdir/env/lib/python3.10/site-packages/huggingface_hub/utils/_validators.py", line 118, in _inner_fn
    return fn(*args, **kwargs)
  File "/workdir/env/lib/python3.10/site-packages/huggingface_hub/file_download.py", line 1195, in hf_hub_download
    metadata = get_hf_file_metadata(
  File "/workdir/env/lib/python3.10/site-packages/huggingface_hub/utils/_validators.py", line 118, in _inner_fn
    return fn(*args, **kwargs)
  File "/workdir/env/lib/python3.10/site-packages/huggingface_hub/file_download.py", line 1541, in get_hf_file_metadata
    hf_raise_for_status(r)
  File "/workdir/env/lib/python3.10/site-packages/huggingface_hub/utils/_errors.py", line 277, in hf_raise_for_status
    raise GatedRepoError(message, response) from e
huggingface_hub.utils._errors.GatedRepoError: 401 Client Error. (Request ID: Root=1-65379682-6afc0bcf57f8c7d30d74697a;a912bdf8-3075-476f-9183-82815a791a64)
Cannot access gated repo for url https://huggingface.co/meta-llama/Llama-2-7b-hf/resolve/main/config.json.
Repo model meta-llama/Llama-2-7b-hf is gated. You must be authenticated to access it.
The above exception was the direct cause of the following exception:
Traceback (most recent call last):
  File "/usr/lib/python3.10/runpy.py", line 196, in _run_module_as_main
    return _run_code(code, main_globals, None,
  File "/usr/lib/python3.10/runpy.py", line 86, in _run_code
    exec(code, run_globals)
  File "/workdir/llama-recipes/src/llama_recipes/finetuning.py", line 270, in <module>
    fire.Fire(main)
  File "/workdir/env/lib/python3.10/site-packages/fire/core.py", line 141, in Fire
    component_trace = _Fire(component, args, parsed_flag_args, context, name)
  File "/workdir/env/lib/python3.10/site-packages/fire/core.py", line 475, in _Fire
    component, remaining_args = _CallAndUpdateTrace(
  File "/workdir/env/lib/python3.10/site-packages/fire/core.py", line 691, in _CallAndUpdateTrace
    component = fn(*varargs, **kwargs)
  File "/workdir/llama-recipes/src/llama_recipes/finetuning.py", line 95, in main
    model = LlamaForCausalLM.from_pretrained(
  File "/workdir/env/lib/python3.10/site-packages/transformers/modeling_utils.py", line 2377, in from_pretrained
    resolved_config_file = cached_file(
  File "/workdir/env/lib/python3.10/site-packages/transformers/utils/hub.py", line 444, in cached_file
    raise EnvironmentError(
OSError: You are trying to access a gated repo.
Make sure to request access at https://huggingface.co/meta-llama/Llama-2-7b-hf and pass a token having permission to this repo either by logging in with `huggingface-cli login` or by passing `token=<your_token>`.
Traceback (most recent call last):
  File "/workdir/env/lib/python3.10/site-packages/huggingface_hub/utils/_errors.py", line 261, in hf_raise_for_status
    response.raise_for_status()
  File "/workdir/env/lib/python3.10/site-packages/requests/models.py", line 1021, in raise_for_status
    raise HTTPError(http_error_msg, response=self)
requests.exceptions.HTTPError: 401 Client Error: Unauthorized for url: https://huggingface.co/meta-llama/Llama-2-7b-hf/resolve/main/config.json
The above exception was the direct cause of the following exception:
Traceback (most recent call last):
  File "/workdir/env/lib/python3.10/site-packages/transformers/utils/hub.py", line 429, in cached_file
    resolved_file = hf_hub_download(
  File "/workdir/env/lib/python3.10/site-packages/huggingface_hub/utils/_validators.py", line 118, in _inner_fn
    return fn(*args, **kwargs)
  File "/workdir/env/lib/python3.10/site-packages/huggingface_hub/file_download.py", line 1195, in hf_hub_download
    metadata = get_hf_file_metadata(
  File "/workdir/env/lib/python3.10/site-packages/huggingface_hub/utils/_validators.py", line 118, in _inner_fn
    return fn(*args, **kwargs)
  File "/workdir/env/lib/python3.10/site-packages/huggingface_hub/file_download.py", line 1541, in get_hf_file_metadata
    hf_raise_for_status(r)
  File "/workdir/env/lib/python3.10/site-packages/huggingface_hub/utils/_errors.py", line 277, in hf_raise_for_status
    raise GatedRepoError(message, response) from e
huggingface_hub.utils._errors.GatedRepoError: 401 Client Error. (Request ID: Root=1-65379682-6afc0bcf57f8c7d30d74697a;a912bdf8-3075-476f-9183-82815a791a64)
Cannot access gated repo for url https://huggingface.co/meta-llama/Llama-2-7b-hf/resolve/main/config.json.
Repo model meta-llama/Llama-2-7b-hf is gated. You must be authenticated to access it.
The above exception was the direct cause of the following exception:
Traceback (most recent call last):
  File "/usr/lib/python3.10/runpy.py", line 196, in _run_module_as_main
    return _run_code(code, main_globals, None,
  File "/usr/lib/python3.10/runpy.py", line 86, in _run_code
    exec(code, run_globals)
  File "/workdir/llama-recipes/src/llama_recipes/finetuning.py", line 270, in <module>
    fire.Fire(main)
  File "/workdir/env/lib/python3.10/site-packages/fire/core.py", line 141, in Fire
    component_trace = _Fire(component, args, parsed_flag_args, context, name)
  File "/workdir/env/lib/python3.10/site-packages/fire/core.py", line 475, in _Fire
    component, remaining_args = _CallAndUpdateTrace(
  File "/workdir/env/lib/python3.10/site-packages/fire/core.py", line 691, in _CallAndUpdateTrace
    component = fn(*varargs, **kwargs)
  File "/workdir/llama-recipes/src/llama_recipes/finetuning.py", line 95, in main
    model = LlamaForCausalLM.from_pretrained(
  File "/workdir/env/lib/python3.10/site-packages/transformers/modeling_utils.py", line 2377, in from_pretrained
    resolved_config_file = cached_file(
  File "/workdir/env/lib/python3.10/site-packages/transformers/utils/hub.py", line 444, in cached_file
    raise EnvironmentError(
OSError: You are trying to access a gated repo.
Make sure to request access at https://huggingface.co/meta-llama/Llama-2-7b-hf and pass a token having permission to this repo either by logging in with `huggingface-cli login` or by passing `token=<your_token>`.